Workbook

Sheet README
A1: 36-Month Rolling Financial Analysis
A3: A complete, fictional worked example of a 36 month rolling forecast built the way a cash
A4: system is actually run. It accompanies the article Cash! Who Owns the Forecast? at
A5: https://www.darlison.com/who-owns-the-forecast/
A7: HOW TO READ IT
A8: Columns run NEWEST FIRST. The far end of the plan, December 2028, is at the left, and time
A9: walks right into the past. Every month carries three columns: Actual, Rolling and Approved.
A10: Actual is what happened, and fills in as each month closes. Rolling is the current best
A11: estimate. Approved is the plan, and does not move until the annual reset.
A13: The weekly Scoreboard takes its targets from APPROVED, never from Rolling. Rolling moves
A14: every month, so a forecast drifting downwards would quietly lower the weekly target and hide
A15: the miss the board exists to show you.
... A129: All numbers are fictional.

Sheet Summary
B1: ="FY"&YEAR(K$1) | E1: ="FY"&YEAR(AU$1) | H1: ="FY"&YEAR(CE$1) | K1: =EOMONTH(N$1,1) | N1: =EOMONTH(Q$1,1) | Q1: =EOMONTH(T$1,1) | T1: =EOMONTH(W$1,1) | W1: =EOMONTH(Z$1,1) | Z1: =EOMONTH(AC$1,1) | AC1: =EOMONTH(AF$1,1) | AF1: =EOMONTH(AI$1,1) | AI1: =EOMONTH(AL$1,1) | AL1: =EOMONTH(AO$1,1) | AO1: =EOMONTH(AR$1,1) | AR1: =EOMONTH(AU$1,1) | AU1: =EOMONTH(AX$1,1) | AX1: =EOMONTH(BA$1,1) | BA1: =EOMONTH(BD$1,1) | BD1: =EOMONTH(BG$1,1) | BG1: =EOMONTH(BJ$1,1) | BJ1: =EOMONTH(BM$1,1) | BM1: =EOMONTH(BP$1,1) | BP1: =EOMONTH(BS$1,1) | BS1: =EOMONTH(BV$1,1) | BV1: =EOMONTH(BY$1,1) | BY1: =EOMONTH(CB$1,1) | CB1: =EOMONTH(CE$1,1) | CE1: =EOMONTH(CH$1,1) | CH1: =EOMONTH(CK$1,1) | CK1: =EOMONTH(CN$1,1) | CN1: =EOMONTH(CQ$1,1) | CQ1: =EOMONTH(CT$1,1) | CT1: =EOMONTH(CW$1,1) | CW1: =EOMONTH(CZ$1,1) | CZ1: =EOMONTH(DC$1,1) | DC1: =EOMONTH(DF$1,1) | DF1: =EOMONTH(DI$1,1) | DI1: =EOMONTH(DL$1,1) | DL1: =Finance!$B$61
B2: Actual | C2: Rolling | D2: Approved | E2: Actual | F2: Rolling | G2: Approved | H2: Actual | I2: Rolling | J2: Approved | K2: Actual | L2: Rolling | M2: Approved | N2: Actual | O2: Rolling | P2: Approved | Q2: Actual | R2: Rolling | S2: Approved | T2: Actual | U2: Rolling | V2: Approved | W2: Actual | X2: Rolling | Y2: Approved | Z2: Actual | AA2: Rolling | AB2: Approved | AC2: Actual | AD2: Rolling | AE2: Approved | AF2: Actual | AG2: Rolling | AH2: Approved | AI2: Actual | AJ2: Rolling | AK2: Approved | AL2: Actual | AM2: Rolling | AN2: Approved | AO2: Actual | AP2: Rolling | AQ2: Approved | AR2: Actual | AS2: Rolling | AT2: Approved | AU2: Actual | AV2: Rolling | AW2: Approved | AX2: Actual | AY2: Rolling | AZ2: Approved | BA2: Actual | BB2: Rolling | BC2: Approved | BD2: Actual | BE2: Rolling | BF2: Approved | BG2: Actual | BH2: Rolling | BI2: Approved | BJ2: Actual | BK2: Rolling | BL2: Approved | BM2: Actual | BN2: Rolling | BO2: Approved | BP2: Actual | BQ2: Rolling | BR2: Approved | BS2: Actual | BT2: Rolling | BU2: Approved | BV2: Actual | BW2: Rolling | BX2: Approved | BY2: Actual | BZ2: Rolling | CA2: Approved | CB2: Actual | CC2: Rolling | CD2: Approved | CE2: Actual | CF2: Rolling | CG2: Approved | CH2: Actual | CI2: Rolling | CJ2: Approved | CK2: Actual | CL2: Rolling | CM2: Approved | CN2: Actual | CO2: Rolling | CP2: Approved | CQ2: Actual | CR2: Rolling | CS2: Approved | CT2: Actual | CU2: Rolling | CV2: Approved | CW2: Actual | CX2: Rolling | CY2: Approved | CZ2: Actual | DA2: Rolling | DB2: Approved | DC2: Actual | DD2: Rolling | DE2: Approved | DF2: Actual | DG2: Rolling | DH2: Approved | DI2: Actual | DJ2: Rolling | DK2: Approved | DL2: Actual | DM2: Rolling | DN2: Approved
A3: Opening Recurring Revenue | B3: =IF(AR3<>"",AR3,IF(AO3<>"",AO3,IF(AL3<>"",AL3,IF(AI3<>"",AI3,IF(AF3<>"",AF3,IF(AC3<>"",AC3,IF(Z3<>"",Z3,IF(W3<>"",W3,IF(T3<>"",T3,IF(Q3<>"",Q3,IF(N3<>"",N3,IF(K3<>"",K3,"")))))))))))) | C3: =IF(AS3<>"",AS3,IF(AP3<>"",AP3,IF(AM3<>"",AM3,IF(AJ3<>"",AJ3,IF(AG3<>"",AG3,IF(AD3<>"",AD3,IF(AA3<>"",AA3,IF(X3<>"",X3,IF(U3<>"",U3,IF(R3<>"",R3,IF(O3<>"",O3,IF(L3<>"",L3,"")))))))))))) | D3: =IF(AT3<>"",AT3,IF(AQ3<>"",AQ3,IF(AN3<>"",AN3,IF(AK3<>"",AK3,IF(AH3<>"",AH3,IF(AE3<>"",AE3,IF(AB3<>"",AB3,IF(Y3<>"",Y3,IF(V3<>"",V3,IF(S3<>"",S3,IF(P3<>"",P3,IF(M3<>"",M3,"")))))))))))) | E3: =IF(CB3<>"",CB3,IF(BY3<>"",BY3,IF(BV3<>"",BV3,IF(BS3<>"",BS3,IF(BP3<>"",BP3,IF(BM3<>"",BM3,IF(BJ3<>"",BJ3,IF(BG3<>"",BG3,IF(BD3<>"",BD3,IF(BA3<>"",BA3,IF(AX3<>"",AX3,IF(AU3<>"",AU3,"")))))))))))) | F3: =IF(CC3<>"",CC3,IF(BZ3<>"",BZ3,IF(BW3<>"",BW3,IF(BT3<>"",BT3,IF(BQ3<>"",BQ3,IF(BN3<>"",BN3,IF(BK3<>"",BK3,IF(BH3<>"",BH3,IF(BE3<>"",BE3,IF(BB3<>"",BB3,IF(AY3<>"",AY3,IF(AV3<>"",AV3,"")))))))))))) | G3: =IF(CD3<>"",CD3,IF(CA3<>"",CA3,IF(BX3<>"",BX3,IF(BU3<>"",BU3,IF(BR3<>"",BR3,IF(BO3<>"",BO3,IF(BL3<>"",BL3,IF(BI3<>"",BI3,IF(BF3<>"",BF3,IF(BC3<>"",BC3,IF(AZ3<>"",AZ3,IF(AW3<>"",AW3,"")))))))))))) | H3: =IF(DL3<>"",DL3,IF(DI3<>"",DI3,IF(DF3<>"",DF3,IF(DC3<>"",DC3,IF(CZ3<>"",CZ3,IF(CW3<>"",CW3,IF(CT3<>"",CT3,IF(CQ3<>"",CQ3,IF(CN3<>"",CN3,IF(CK3<>"",CK3,IF(CH3<>"",CH3,IF(CE3<>"",CE3,"")))))))))))) | I3: =IF(DM3<>"",DM3,IF(DJ3<>"",DJ3,IF(DG3<>"",DG3,IF(DD3<>"",DD3,IF(DA3<>"",DA3,IF(CX3<>"",CX3,IF(CU3<>"",CU3,IF(CR3<>"",CR3,IF(CO3<>"",CO3,IF(CL3<>"",CL3,IF(CI3<>"",CI3,IF(CF3<>"",CF3,"")))))))))))) | J3: =IF(DN3<>"",DN3,IF(DK3<>"",DK3,IF(DH3<>"",DH3,IF(DE3<>"",DE3,IF(DB3<>"",DB3,IF(CY3<>"",CY3,IF(CV3<>"",CV3,IF(CS3<>"",CS3,IF(CP3<>"",CP3,IF(CM3<>"",CM3,IF(CJ3<>"",CJ3,IF(CG3<>"",CG3,"")))))))))))) | K3: =IF(COUNT('Summary'!N6)=1,'Summary'!N6,"") | L3: ='Summary'!O6 | M3: ='Summary'!P6 | N3: =IF(COUNT('Summary'!Q6)=1,'Summary'!Q6,"") | O3: ='Summary'!R6 | P3: ='Summary'!S6 | Q3: =IF(COUNT('Summary'!T6)=1,'Summary'!T6,"") | R3: ='Summary'!U6 | S3: ='Summary'!V6 | T3: =IF(COUNT('Summary'!W6)=1,'Summary'!W6,"") | U3: ='Summary'!X6 | V3: ='Summary'!Y6 | W3: =IF(COUNT('Summary'!Z6)=1,'Summary'!Z6,"") | X3: ='Summary'!AA6 | Y3: ='Summary'!AB6 | Z3: =IF(COUNT('Summary'!AC6)=1,'Summary'!AC6,"") | AA3: ='Summary'!AD6 | AB3: ='Summary'!AE6 | AC3: =IF(COUNT('Summary'!AF6)=1,'Summary'!AF6,"") | AD3: ='Summary'!AG6 | AE3: ='Summary'!AH6 | AF3: =IF(COUNT('Summary'!AI6)=1,'Summary'!AI6,"") | AG3: ='Summary'!AJ6 | AH3: ='Summary'!AK6 | AI3: =IF(COUNT('Summary'!AL6)=1,'Summary'!AL6,"") | AJ3: ='Summary'!AM6 | AK3: ='Summary'!AN6 | AL3: =IF(COUNT('Summary'!AO6)=1,'Summary'!AO6,"") | AM3: ='Summary'!AP6 | AN3: ='Summary'!AQ6 | AO3: =IF(COUNT('Summary'!AR6)=1,'Summary'!AR6,"") | AP3: ='Summary'!AS6 | AQ3: ='Summary'!AT6 | AR3: =IF(COUNT('Summary'!AU6)=1,'Summary'!AU6,"") | AS3: ='Summary'!AV6 | AT3: ='Summary'!AW6 | AU3: =IF(COUNT('Summary'!AX6)=1,'Summary'!AX6,"") | AV3: ='Summary'!AY6 | AW3: ='Summary'!AZ6 | AX3: =IF(COUNT('Summary'!BA6)=1,'Summary'!BA6,"") | AY3: ='Summary'!BB6 | AZ3: ='Summary'!BC6 | BA3: =IF(COUNT('Summary'!BD6)=1,'Summary'!BD6,"") | BB3: ='Summary'!BE6 | BC3: ='Summary'!BF6 | BD3: =IF(COUNT('Summary'!BG6)=1,'Summary'!BG6,"") | BE3: ='Summary'!BH6 | BF3: ='Summary'!BI6 | BG3: =IF(COUNT('Summary'!BJ6)=1,'Summary'!BJ6,"") | BH3: ='Summary'!BK6 | BI3: ='Summary'!BL6 | BJ3: =IF(COUNT('Summary'!BM6)=1,'Summary'!BM6,"") | BK3: ='Summary'!BN6 | BL3: ='Summary'!BO6 | BM3: =IF(COUNT('Summary'!BP6)=1,'Summary'!BP6,"") | BN3: ='Summary'!BQ6 | BO3: ='Summary'!BR6 | BP3: =IF(COUNT('Summary'!BS6)=1,'Summary'!BS6,"") | BQ3: ='Summary'!BT6 | BR3: ='Summary'!BU6 | BS3: =IF(COUNT('Summary'!BV6)=1,'Summary'!BV6,"") | BT3: ='Summary'!BW6 | BU3: ='Summary'!BX6 | BV3: =IF(COUNT('Summary'!BY6)=1,'Summary'!BY6,"") | BW3: ='Summary'!BZ6 | BX3: ='Summary'!CA6 | BY3: =IF(COUNT('Summary'!CB6)=1,'Summary'!CB6,"") | BZ3: ='Summary'!CC6 | CA3: ='Summary'!CD6 | CB3: =IF(COUNT('Summary'!CE6)=1,'Summary'!CE6,"") | CC3: ='Summary'!CF6 | CD3: ='Summary'!CG6 | CE3: =IF(COUNT('Summary'!CH6)=1,'Summary'!CH6,"") | CF3: ='Summary'!CI6 | CG3: ='Summary'!CJ6 | CH3: =IF(COUNT('Summary'!CK6)=1,'Summary'!CK6,"") | CI3: ='Summary'!CL6 | CJ3: ='Summary'!CM6 | CK3: =IF(COUNT('Summary'!CN6)=1,'Summary'!CN6,"") | CL3: ='Summary'!CO6 | CM3: ='Summary'!CP6 | CN3: =IF(COUNT('Summary'!CQ6)=1,'Summary'!CQ6,"") | CO3: ='Summary'!CR6 | CP3: ='Summary'!CS6 | CQ3: =IF(COUNT('Summary'!CT6)=1,'Summary'!CT6,"") | CR3: ='Summary'!CU6 | CS3: ='Summary'!CV6 | CT3: =IF(COUNT('Summary'!CW6)=1,'Summary'!CW6,"") | CU3: ='Summary'!CX6 | CV3: ='Summary'!CY6 | CW3: =IF(COUNT('Summary'!CZ6)=1,'Summary'!CZ6,"") | CX3: ='Summary'!DA6 | CY3: ='Summary'!DB6 | CZ3: =IF(COUNT('Summary'!DC6)=1,'Summary'!DC6,"") | DA3: ='Summary'!DD6 | DB3: ='Summary'!DE6 | DC3: =IF(COUNT('Summary'!DF6)=1,'Summary'!DF6,"") | DD3: ='Summary'!DG6 | DE3: ='Summary'!DH6 | DF3: =IF(COUNT('Summary'!DI6)=1,'Summary'!DI6,"") | DG3: ='Summary'!DJ6 | DH3: ='Summary'!DK6 | DI3: =IF(COUNT('Summary'!DL6)=1,'Summary'!DL6,"") | DJ3: ='Summary'!DM6 | DK3: ='Summary'!DN6 | DL3: =IF(COUNT(Finance!$B$63)=1,Finance!$B$63,"") | DM3: =Finance!$B$63 | DN3: =Finance!$B$63
A4: New Recurring Revenue | B4: =IF(COUNT(AR4,AO4,AL4,AI4,AF4,AC4,Z4,W4,T4,Q4,N4,K4)=0,"",SUM(AR4,AO4,AL4,AI4,AF4,AC4,Z4,W4,T4,Q4,N4,K4)) | C4: =IF(COUNT(AS4,AP4,AM4,AJ4,AG4,AD4,AA4,X4,U4,R4,O4,L4)=0,"",SUM(AS4,AP4,AM4,AJ4,AG4,AD4,AA4,X4,U4,R4,O4,L4)) | D4: =IF(COUNT(AT4,AQ4,AN4,AK4,AH4,AE4,AB4,Y4,V4,S4,P4,M4)=0,"",SUM(AT4,AQ4,AN4,AK4,AH4,AE4,AB4,Y4,V4,S4,P4,M4)) | E4: =IF(COUNT(CB4,BY4,BV4,BS4,BP4,BM4,BJ4,BG4,BD4,BA4,AX4,AU4)=0,"",SUM(CB4,BY4,BV4,BS4,BP4,BM4,BJ4,BG4,BD4,BA4,AX4,AU4)) | F4: =IF(COUNT(CC4,BZ4,BW4,BT4,BQ4,BN4,BK4,BH4,BE4,BB4,AY4,AV4)=0,"",SUM(CC4,BZ4,BW4,BT4,BQ4,BN4,BK4,BH4,BE4,BB4,AY4,AV4)) | G4: =IF(COUNT(CD4,CA4,BX4,BU4,BR4,BO4,BL4,BI4,BF4,BC4,AZ4,AW4)=0,"",SUM(CD4,CA4,BX4,BU4,BR4,BO4,BL4,BI4,BF4,BC4,AZ4,AW4)) | H4: =IF(COUNT(DL4,DI4,DF4,DC4,CZ4,CW4,CT4,CQ4,CN4,CK4,CH4,CE4)=0,"",SUM(DL4,DI4,DF4,DC4,CZ4,CW4,CT4,CQ4,CN4,CK4,CH4,CE4)) | I4: =IF(COUNT(DM4,DJ4,DG4,DD4,DA4,CX4,CU4,CR4,CO4,CL4,CI4,CF4)=0,"",SUM(DM4,DJ4,DG4,DD4,DA4,CX4,CU4,CR4,CO4,CL4,CI4,CF4)) | J4: =IF(COUNT(DN4,DK4,DH4,DE4,DB4,CY4,CV4,CS4,CP4,CM4,CJ4,CG4)=0,"",SUM(DN4,DK4,DH4,DE4,DB4,CY4,CV4,CS4,CP4,CM4,CJ4,CG4)) | K4: =IF(COUNT('Sales'!K8)=1,'Sales'!K8,"") | L4: ='Sales'!L8 | M4: ='Sales'!M8 | N4: =IF(COUNT('Sales'!N8)=1,'Sales'!N8,"") | O4: ='Sales'!O8 | P4: ='Sales'!P8 | Q4: =IF(COUNT('Sales'!Q8)=1,'Sales'!Q8,"") | R4: ='Sales'!R8 | S4: ='Sales'!S8 | T4: =IF(COUNT('Sales'!T8)=1,'Sales'!T8,"") | U4: ='Sales'!U8 | V4: ='Sales'!V8 | W4: =IF(COUNT('Sales'!W8)=1,'Sales'!W8,"") | X4: ='Sales'!X8 | Y4: ='Sales'!Y8 | Z4: =IF(COUNT('Sales'!Z8)=1,'Sales'!Z8,"") | AA4: ='Sales'!AA8 | AB4: ='Sales'!AB8 | AC4: =IF(COUNT('Sales'!AC8)=1,'Sales'!AC8,"") | AD4: ='Sales'!AD8 | AE4: ='Sales'!AE8 | AF4: =IF(COUNT('Sales'!AF8)=1,'Sales'!AF8,"") | AG4: ='Sales'!AG8 | AH4: ='Sales'!AH8 | AI4: =IF(COUNT('Sales'!AI8)=1,'Sales'!AI8,"") | AJ4: ='Sales'!AJ8 | AK4: ='Sales'!AK8 | AL4: =IF(COUNT('Sales'!AL8)=1,'Sales'!AL8,"") | AM4: ='Sales'!AM8 | AN4: ='Sales'!AN8 | AO4: =IF(COUNT('Sales'!AO8)=1,'Sales'!AO8,"") | AP4: ='Sales'!AP8 | AQ4: ='Sales'!AQ8 | AR4: =IF(COUNT('Sales'!AR8)=1,'Sales'!AR8,"") | AS4: ='Sales'!AS8 | AT4: ='Sales'!AT8 | AU4: =IF(COUNT('Sales'!AU8)=1,'Sales'!AU8,"") | AV4: ='Sales'!AV8 | AW4: ='Sales'!AW8 | AX4: =IF(COUNT('Sales'!AX8)=1,'Sales'!AX8,"") | AY4: ='Sales'!AY8 | AZ4: ='Sales'!AZ8 | BA4: =IF(COUNT('Sales'!BA8)=1,'Sales'!BA8,"") | BB4: ='Sales'!BB8 | BC4: ='Sales'!BC8 | BD4: =IF(COUNT('Sales'!BD8)=1,'Sales'!BD8,"") | BE4: ='Sales'!BE8 | BF4: ='Sales'!BF8 | BG4: =IF(COUNT('Sales'!BG8)=1,'Sales'!BG8,"") | BH4: ='Sales'!BH8 | BI4: ='Sales'!BI8 | BJ4: =IF(COUNT('Sales'!BJ8)=1,'Sales'!BJ8,"") | BK4: ='Sales'!BK8 | BL4: ='Sales'!BL8 | BM4: =IF(COUNT('Sales'!BM8)=1,'Sales'!BM8,"") | BN4: ='Sales'!BN8 | BO4: ='Sales'!BO8 | BP4: =IF(COUNT('Sales'!BP8)=1,'Sales'!BP8,"") | BQ4: ='Sales'!BQ8 | BR4: ='Sales'!BR8 | BS4: =IF(COUNT('Sales'!BS8)=1,'Sales'!BS8,"") | BT4: ='Sales'!BT8 | BU4: ='Sales'!BU8 | BV4: =IF(COUNT('Sales'!BV8)=1,'Sales'!BV8,"") | BW4: ='Sales'!BW8 | BX4: ='Sales'!BX8 | BY4: =IF(COUNT('Sales'!BY8)=1,'Sales'!BY8,"") | BZ4: ='Sales'!BZ8 | CA4: ='Sales'!CA8 | CB4: =IF(COUNT('Sales'!CB8)=1,'Sales'!CB8,"") | CC4: ='Sales'!CC8 | CD4: ='Sales'!CD8 | CE4: =IF(COUNT('Sales'!CE8)=1,'Sales'!CE8,"") | CF4: ='Sales'!CF8 | CG4: ='Sales'!CG8 | CH4: =IF(COUNT('Sales'!CH8)=1,'Sales'!CH8,"") | CI4: ='Sales'!CI8 | CJ4: ='Sales'!CJ8 | CK4: =IF(COUNT('Sales'!CK8)=1,'Sales'!CK8,"") | CL4: ='Sales'!CL8 | CM4: ='Sales'!CM8 | CN4: =IF(COUNT('Sales'!CN8)=1,'Sales'!CN8,"") | CO4: ='Sales'!CO8 | CP4: ='Sales'!CP8 | CQ4: =IF(COUNT('Sales'!CQ8)=1,'Sales'!CQ8,"") | CR4: ='Sales'!CR8 | CS4: ='Sales'!CS8 | CT4: =IF(COUNT('Sales'!CT8)=1,'Sales'!CT8,"") | CU4: ='Sales'!CU8 | CV4: ='Sales'!CV8 | CW4: =IF(COUNT('Sales'!CW8)=1,'Sales'!CW8,"") | CX4: ='Sales'!CX8 | CY4: ='Sales'!CY8 | CZ4: =IF(COUNT('Sales'!CZ8)=1,'Sales'!CZ8,"") | DA4: ='Sales'!DA8 | DB4: ='Sales'!DB8 | DC4: =IF(COUNT('Sales'!DC8)=1,'Sales'!DC8,"") | DD4: ='Sales'!DD8 | DE4: ='Sales'!DE8 | DF4: =IF(COUNT('Sales'!DF8)=1,'Sales'!DF8,"") | DG4: ='Sales'!DG8 | DH4: ='Sales'!DH8 | DI4: =IF(COUNT('Sales'!DI8)=1,'Sales'!DI8,"") | DJ4: ='Sales'!DJ8 | DK4: ='Sales'!DK8 | DL4: =IF(COUNT('Sales'!DL8)=1,'Sales'!DL8,"") | DM4: ='Sales'!DM8 | DN4: ='Sales'!DN8
A5: Net Change on Existing | B5: =IF(COUNT(AR5,AO5,AL5,AI5,AF5,AC5,Z5,W5,T5,Q5,N5,K5)=0,"",SUM(AR5,AO5,AL5,AI5,AF5,AC5,Z5,W5,T5,Q5,N5,K5)) | C5: =IF(COUNT(AS5,AP5,AM5,AJ5,AG5,AD5,AA5,X5,U5,R5,O5,L5)=0,"",SUM(AS5,AP5,AM5,AJ5,AG5,AD5,AA5,X5,U5,R5,O5,L5)) | D5: =IF(COUNT(AT5,AQ5,AN5,AK5,AH5,AE5,AB5,Y5,V5,S5,P5,M5)=0,"",SUM(AT5,AQ5,AN5,AK5,AH5,AE5,AB5,Y5,V5,S5,P5,M5)) | E5: =IF(COUNT(CB5,BY5,BV5,BS5,BP5,BM5,BJ5,BG5,BD5,BA5,AX5,AU5)=0,"",SUM(CB5,BY5,BV5,BS5,BP5,BM5,BJ5,BG5,BD5,BA5,AX5,AU5)) | F5: =IF(COUNT(CC5,BZ5,BW5,BT5,BQ5,BN5,BK5,BH5,BE5,BB5,AY5,AV5)=0,"",SUM(CC5,BZ5,BW5,BT5,BQ5,BN5,BK5,BH5,BE5,BB5,AY5,AV5)) | G5: =IF(COUNT(CD5,CA5,BX5,BU5,BR5,BO5,BL5,BI5,BF5,BC5,AZ5,AW5)=0,"",SUM(CD5,CA5,BX5,BU5,BR5,BO5,BL5,BI5,BF5,BC5,AZ5,AW5)) | H5: =IF(COUNT(DL5,DI5,DF5,DC5,CZ5,CW5,CT5,CQ5,CN5,CK5,CH5,CE5)=0,"",SUM(DL5,DI5,DF5,DC5,CZ5,CW5,CT5,CQ5,CN5,CK5,CH5,CE5)) | I5: =IF(COUNT(DM5,DJ5,DG5,DD5,DA5,CX5,CU5,CR5,CO5,CL5,CI5,CF5)=0,"",SUM(DM5,DJ5,DG5,DD5,DA5,CX5,CU5,CR5,CO5,CL5,CI5,CF5)) | J5: =IF(COUNT(DN5,DK5,DH5,DE5,DB5,CY5,CV5,CS5,CP5,CM5,CJ5,CG5)=0,"",SUM(DN5,DK5,DH5,DE5,DB5,CY5,CV5,CS5,CP5,CM5,CJ5,CG5)) | K5: =IF(COUNT('Customer Success'!K11)=1,'Customer Success'!K11,"") | L5: ='Customer Success'!L11 | M5: ='Customer Success'!M11 | N5: =IF(COUNT('Customer Success'!N11)=1,'Customer Success'!N11,"") | O5: ='Customer Success'!O11 | P5: ='Customer Success'!P11 | Q5: =IF(COUNT('Customer Success'!Q11)=1,'Customer Success'!Q11,"") | R5: ='Customer Success'!R11 | S5: ='Customer Success'!S11 | T5: =IF(COUNT('Customer Success'!T11)=1,'Customer Success'!T11,"") | U5: ='Customer Success'!U11 | V5: ='Customer Success'!V11 | W5: =IF(COUNT('Customer Success'!W11)=1,'Customer Success'!W11,"") | X5: ='Customer Success'!X11 | Y5: ='Customer Success'!Y11 | Z5: =IF(COUNT('Customer Success'!Z11)=1,'Customer Success'!Z11,"") | AA5: ='Customer Success'!AA11 | AB5: ='Customer Success'!AB11 | AC5: =IF(COUNT('Customer Success'!AC11)=1,'Customer Success'!AC11,"") | AD5: ='Customer Success'!AD11 | AE5: ='Customer Success'!AE11 | AF5: =IF(COUNT('Customer Success'!AF11)=1,'Customer Success'!AF11,"") | AG5: ='Customer Success'!AG11 | AH5: ='Customer Success'!AH11 | AI5: =IF(COUNT('Customer Success'!AI11)=1,'Customer Success'!AI11,"") | AJ5: ='Customer Success'!AJ11 | AK5: ='Customer Success'!AK11 | AL5: =IF(COUNT('Customer Success'!AL11)=1,'Customer Success'!AL11,"") | AM5: ='Customer Success'!AM11 | AN5: ='Customer Success'!AN11 | AO5: =IF(COUNT('Customer Success'!AO11)=1,'Customer Success'!AO11,"") | AP5: ='Customer Success'!AP11 | AQ5: ='Customer Success'!AQ11 | AR5: =IF(COUNT('Customer Success'!AR11)=1,'Customer Success'!AR11,"") | AS5: ='Customer Success'!AS11 | AT5: ='Customer Success'!AT11 | AU5: =IF(COUNT('Customer Success'!AU11)=1,'Customer Success'!AU11,"") | AV5: ='Customer Success'!AV11 | AW5: ='Customer Success'!AW11 | AX5: =IF(COUNT('Customer Success'!AX11)=1,'Customer Success'!AX11,"") | AY5: ='Customer Success'!AY11 | AZ5: ='Customer Success'!AZ11 | BA5: =IF(COUNT('Customer Success'!BA11)=1,'Customer Success'!BA11,"") | BB5: ='Customer Success'!BB11 | BC5: ='Customer Success'!BC11 | BD5: =IF(COUNT('Customer Success'!BD11)=1,'Customer Success'!BD11,"") | BE5: ='Customer Success'!BE11 | BF5: ='Customer Success'!BF11 | BG5: =IF(COUNT('Customer Success'!BG11)=1,'Customer Success'!BG11,"") | BH5: ='Customer Success'!BH11 | BI5: ='Customer Success'!BI11 | BJ5: =IF(COUNT('Customer Success'!BJ11)=1,'Customer Success'!BJ11,"") | BK5: ='Customer Success'!BK11 | BL5: ='Customer Success'!BL11 | BM5: =IF(COUNT('Customer Success'!BM11)=1,'Customer Success'!BM11,"") | BN5: ='Customer Success'!BN11 | BO5: ='Customer Success'!BO11 | BP5: =IF(COUNT('Customer Success'!BP11)=1,'Customer Success'!BP11,"") | BQ5: ='Customer Success'!BQ11 | BR5: ='Customer Success'!BR11 | BS5: =IF(COUNT('Customer Success'!BS11)=1,'Customer Success'!BS11,"") | BT5: ='Customer Success'!BT11 | BU5: ='Customer Success'!BU11 | BV5: =IF(COUNT('Customer Success'!BV11)=1,'Customer Success'!BV11,"") | BW5: ='Customer Success'!BW11 | BX5: ='Customer Success'!BX11 | BY5: =IF(COUNT('Customer Success'!BY11)=1,'Customer Success'!BY11,"") | BZ5: ='Customer Success'!BZ11 | CA5: ='Customer Success'!CA11 | CB5: =IF(COUNT('Customer Success'!CB11)=1,'Customer Success'!CB11,"") | CC5: ='Customer Success'!CC11 | CD5: ='Customer Success'!CD11 | CE5: =IF(COUNT('Customer Success'!CE11)=1,'Customer Success'!CE11,"") | CF5: ='Customer Success'!CF11 | CG5: ='Customer Success'!CG11 | CH5: =IF(COUNT('Customer Success'!CH11)=1,'Customer Success'!CH11,"") | CI5: ='Customer Success'!CI11 | CJ5: ='Customer Success'!CJ11 | CK5: =IF(COUNT('Customer Success'!CK11)=1,'Customer Success'!CK11,"") | CL5: ='Customer Success'!CL11 | CM5: ='Customer Success'!CM11 | CN5: =IF(COUNT('Customer Success'!CN11)=1,'Customer Success'!CN11,"") | CO5: ='Customer Success'!CO11 | CP5: ='Customer Success'!CP11 | CQ5: =IF(COUNT('Customer Success'!CQ11)=1,'Customer Success'!CQ11,"") | CR5: ='Customer Success'!CR11 | CS5: ='Customer Success'!CS11 | CT5: =IF(COUNT('Customer Success'!CT11)=1,'Customer Success'!CT11,"") | CU5: ='Customer Success'!CU11 | CV5: ='Customer Success'!CV11 | CW5: =IF(COUNT('Customer Success'!CW11)=1,'Customer Success'!CW11,"") | CX5: ='Customer Success'!CX11 | CY5: ='Customer Success'!CY11 | CZ5: =IF(COUNT('Customer Success'!CZ11)=1,'Customer Success'!CZ11,"") | DA5: ='Customer Success'!DA11 | DB5: ='Customer Success'!DB11 | DC5: =IF(COUNT('Customer Success'!DC11)=1,'Customer Success'!DC11,"") | DD5: ='Customer Success'!DD11 | DE5: ='Customer Success'!DE11 | DF5: =IF(COUNT('Customer Success'!DF11)=1,'Customer Success'!DF11,"") | DG5: ='Customer Success'!DG11 | DH5: ='Customer Success'!DH11 | DI5: =IF(COUNT('Customer Success'!DI11)=1,'Customer Success'!DI11,"") | DJ5: ='Customer Success'!DJ11 | DK5: ='Customer Success'!DK11 | DL5: =IF(COUNT('Customer Success'!DL11)=1,'Customer Success'!DL11,"") | DM5: ='Customer Success'!DM11 | DN5: ='Customer Success'!DN11
A6: Closing Recurring Revenue | B6: =IF(K6<>"",K6,IF(N6<>"",N6,IF(Q6<>"",Q6,IF(T6<>"",T6,IF(W6<>"",W6,IF(Z6<>"",Z6,IF(AC6<>"",AC6,IF(AF6<>"",AF6,IF(AI6<>"",AI6,IF(AL6<>"",AL6,IF(AO6<>"",AO6,IF(AR6<>"",AR6,"")))))))))))) | C6: =IF(L6<>"",L6,IF(O6<>"",O6,IF(R6<>"",R6,IF(U6<>"",U6,IF(X6<>"",X6,IF(AA6<>"",AA6,IF(AD6<>"",AD6,IF(AG6<>"",AG6,IF(AJ6<>"",AJ6,IF(AM6<>"",AM6,IF(AP6<>"",AP6,IF(AS6<>"",AS6,"")))))))))))) | D6: =IF(M6<>"",M6,IF(P6<>"",P6,IF(S6<>"",S6,IF(V6<>"",V6,IF(Y6<>"",Y6,IF(AB6<>"",AB6,IF(AE6<>"",AE6,IF(AH6<>"",AH6,IF(AK6<>"",AK6,IF(AN6<>"",AN6,IF(AQ6<>"",AQ6,IF(AT6<>"",AT6,"")))))))))))) | E6: =IF(AU6<>"",AU6,IF(AX6<>"",AX6,IF(BA6<>"",BA6,IF(BD6<>"",BD6,IF(BG6<>"",BG6,IF(BJ6<>"",BJ6,IF(BM6<>"",BM6,IF(BP6<>"",BP6,IF(BS6<>"",BS6,IF(BV6<>"",BV6,IF(BY6<>"",BY6,IF(CB6<>"",CB6,"")))))))))))) | F6: =IF(AV6<>"",AV6,IF(AY6<>"",AY6,IF(BB6<>"",BB6,IF(BE6<>"",BE6,IF(BH6<>"",BH6,IF(BK6<>"",BK6,IF(BN6<>"",BN6,IF(BQ6<>"",BQ6,IF(BT6<>"",BT6,IF(BW6<>"",BW6,IF(BZ6<>"",BZ6,IF(CC6<>"",CC6,"")))))))))))) | G6: =IF(AW6<>"",AW6,IF(AZ6<>"",AZ6,IF(BC6<>"",BC6,IF(BF6<>"",BF6,IF(BI6<>"",BI6,IF(BL6<>"",BL6,IF(BO6<>"",BO6,IF(BR6<>"",BR6,IF(BU6<>"",BU6,IF(BX6<>"",BX6,IF(CA6<>"",CA6,IF(CD6<>"",CD6,"")))))))))))) | H6: =IF(CE6<>"",CE6,IF(CH6<>"",CH6,IF(CK6<>"",CK6,IF(CN6<>"",CN6,IF(CQ6<>"",CQ6,IF(CT6<>"",CT6,IF(CW6<>"",CW6,IF(CZ6<>"",CZ6,IF(DC6<>"",DC6,IF(DF6<>"",DF6,IF(DI6<>"",DI6,IF(DL6<>"",DL6,"")))))))))))) | I6: =IF(CF6<>"",CF6,IF(CI6<>"",CI6,IF(CL6<>"",CL6,IF(CO6<>"",CO6,IF(CR6<>"",CR6,IF(CU6<>"",CU6,IF(CX6<>"",CX6,IF(DA6<>"",DA6,IF(DD6<>"",DD6,IF(DG6<>"",DG6,IF(DJ6<>"",DJ6,IF(DM6<>"",DM6,"")))))))))))) | J6: =IF(CG6<>"",CG6,IF(CJ6<>"",CJ6,IF(CM6<>"",CM6,IF(CP6<>"",CP6,IF(CS6<>"",CS6,IF(CV6<>"",CV6,IF(CY6<>"",CY6,IF(DB6<>"",DB6,IF(DE6<>"",DE6,IF(DH6<>"",DH6,IF(DK6<>"",DK6,IF(DN6<>"",DN6,"")))))))))))) | K6: =IF(COUNT(K3,K4,K5)=3,K3+K4+K5,"") | L6: =L3+L4+L5 | M6: =M3+M4+M5 | N6: =IF(COUNT(N3,N4,N5)=3,N3+N4+N5,"") | O6: =O3+O4+O5 | P6: =P3+P4+P5 | Q6: =IF(COUNT(Q3,Q4,Q5)=3,Q3+Q4+Q5,"") | R6: =R3+R4+R5 | S6: =S3+S4+S5 | T6: =IF(COUNT(T3,T4,T5)=3,T3+T4+T5,"") | U6: =U3+U4+U5 | V6: =V3+V4+V5 | W6: =IF(COUNT(W3,W4,W5)=3,W3+W4+W5,"") | X6: =X3+X4+X5 | Y6: =Y3+Y4+Y5 | Z6: =IF(COUNT(Z3,Z4,Z5)=3,Z3+Z4+Z5,"") | AA6: =AA3+AA4+AA5 | AB6: =AB3+AB4+AB5 | AC6: =IF(COUNT(AC3,AC4,AC5)=3,AC3+AC4+AC5,"") | AD6: =AD3+AD4+AD5 | AE6: =AE3+AE4+AE5 | AF6: =IF(COUNT(AF3,AF4,AF5)=3,AF3+AF4+AF5,"") | AG6: =AG3+AG4+AG5 | AH6: =AH3+AH4+AH5 | AI6: =IF(COUNT(AI3,AI4,AI5)=3,AI3+AI4+AI5,"") | AJ6: =AJ3+AJ4+AJ5 | AK6: =AK3+AK4+AK5 | AL6: =IF(COUNT(AL3,AL4,AL5)=3,AL3+AL4+AL5,"") | AM6: =AM3+AM4+AM5 | AN6: =AN3+AN4+AN5 | AO6: =IF(COUNT(AO3,AO4,AO5)=3,AO3+AO4+AO5,"") | AP6: =AP3+AP4+AP5 | AQ6: =AQ3+AQ4+AQ5 | AR6: =IF(COUNT(AR3,AR4,AR5)=3,AR3+AR4+AR5,"") | AS6: =AS3+AS4+AS5 | AT6: =AT3+AT4+AT5 | AU6: =IF(COUNT(AU3,AU4,AU5)=3,AU3+AU4+AU5,"") | AV6: =AV3+AV4+AV5 | AW6: =AW3+AW4+AW5 | AX6: =IF(COUNT(AX3,AX4,AX5)=3,AX3+AX4+AX5,"") | AY6: =AY3+AY4+AY5 | AZ6: =AZ3+AZ4+AZ5 | BA6: =IF(COUNT(BA3,BA4,BA5)=3,BA3+BA4+BA5,"") | BB6: =BB3+BB4+BB5 | BC6: =BC3+BC4+BC5 | BD6: =IF(COUNT(BD3,BD4,BD5)=3,BD3+BD4+BD5,"") | BE6: =BE3+BE4+BE5 | BF6: =BF3+BF4+BF5 | BG6: =IF(COUNT(BG3,BG4,BG5)=3,BG3+BG4+BG5,"") | BH6: =BH3+BH4+BH5 | BI6: =BI3+BI4+BI5 | BJ6: =IF(COUNT(BJ3,BJ4,BJ5)=3,BJ3+BJ4+BJ5,"") | BK6: =BK3+BK4+BK5 | BL6: =BL3+BL4+BL5 | BM6: =IF(COUNT(BM3,BM4,BM5)=3,BM3+BM4+BM5,"") | BN6: =BN3+BN4+BN5 | BO6: =BO3+BO4+BO5 | BP6: =IF(COUNT(BP3,BP4,BP5)=3,BP3+BP4+BP5,"") | BQ6: =BQ3+BQ4+BQ5 | BR6: =BR3+BR4+BR5 | BS6: =IF(COUNT(BS3,BS4,BS5)=3,BS3+BS4+BS5,"") | BT6: =BT3+BT4+BT5 | BU6: =BU3+BU4+BU5 | BV6: =IF(COUNT(BV3,BV4,BV5)=3,BV3+BV4+BV5,"") | BW6: =BW3+BW4+BW5 | BX6: =BX3+BX4+BX5 | BY6: =IF(COUNT(BY3,BY4,BY5)=3,BY3+BY4+BY5,"") | BZ6: =BZ3+BZ4+BZ5 | CA6: =CA3+CA4+CA5 | CB6: =IF(COUNT(CB3,CB4,CB5)=3,CB3+CB4+CB5,"") | CC6: =CC3+CC4+CC5 | CD6: =CD3+CD4+CD5 | CE6: =IF(COUNT(CE3,CE4,CE5)=3,CE3+CE4+CE5,"") | CF6: =CF3+CF4+CF5 | CG6: =CG3+CG4+CG5 | CH6: =IF(COUNT(CH3,CH4,CH5)=3,CH3+CH4+CH5,"") | CI6: =CI3+CI4+CI5 | CJ6: =CJ3+CJ4+CJ5 | CK6: =IF(COUNT(CK3,CK4,CK5)=3,CK3+CK4+CK5,"") | CL6: =CL3+CL4+CL5 | CM6: =CM3+CM4+CM5 | CN6: =IF(COUNT(CN3,CN4,CN5)=3,CN3+CN4+CN5,"") | CO6: =CO3+CO4+CO5 | CP6: =CP3+CP4+CP5 | CQ6: =IF(COUNT(CQ3,CQ4,CQ5)=3,CQ3+CQ4+CQ5,"") | CR6: =CR3+CR4+CR5 | CS6: =CS3+CS4+CS5 | CT6: =IF(COUNT(CT3,CT4,CT5)=3,CT3+CT4+CT5,"") | CU6: =CU3+CU4+CU5 | CV6: =CV3+CV4+CV5 | CW6: =IF(COUNT(CW3,CW4,CW5)=3,CW3+CW4+CW5,"") | CX6: =CX3+CX4+CX5 | CY6: =CY3+CY4+CY5 | CZ6: =IF(COUNT(CZ3,CZ4,CZ5)=3,CZ3+CZ4+CZ5,"") | DA6: =DA3+DA4+DA5 | DB6: =DB3+DB4+DB5 | DC6: =IF(COUNT(DC3,DC4,DC5)=3,DC3+DC4+DC5,"") | DD6: =DD3+DD4+DD5 | DE6: =DE3+DE4+DE5 | DF6: =IF(COUNT(DF3,DF4,DF5)=3,DF3+DF4+DF5,"") | DG6: =DG3+DG4+DG5 | DH6: =DH3+DH4+DH5 | DI6: =IF(COUNT(DI3,DI4,DI5)=3,DI3+DI4+DI5,"") | DJ6: =DJ3+DJ4+DJ5 | DK6: =DK3+DK4+DK5 | DL6: =IF(COUNT(DL3,DL4,DL5)=3,DL3+DL4+DL5,"") | DM6: =DM3+DM4+DM5 | DN6: =DN3+DN4+DN5
A7: Revenue | B7: =IF(COUNT(AR7,AO7,AL7,AI7,AF7,AC7,Z7,W7,T7,Q7,N7,K7)=0,"",SUM(AR7,AO7,AL7,AI7,AF7,AC7,Z7,W7,T7,Q7,N7,K7)) | C7: =IF(COUNT(AS7,AP7,AM7,AJ7,AG7,AD7,AA7,X7,U7,R7,O7,L7)=0,"",SUM(AS7,AP7,AM7,AJ7,AG7,AD7,AA7,X7,U7,R7,O7,L7)) | D7: =IF(COUNT(AT7,AQ7,AN7,AK7,AH7,AE7,AB7,Y7,V7,S7,P7,M7)=0,"",SUM(AT7,AQ7,AN7,AK7,AH7,AE7,AB7,Y7,V7,S7,P7,M7)) | E7: =IF(COUNT(CB7,BY7,BV7,BS7,BP7,BM7,BJ7,BG7,BD7,BA7,AX7,AU7)=0,"",SUM(CB7,BY7,BV7,BS7,BP7,BM7,BJ7,BG7,BD7,BA7,AX7,AU7)) | F7: =IF(COUNT(CC7,BZ7,BW7,BT7,BQ7,BN7,BK7,BH7,BE7,BB7,AY7,AV7)=0,"",SUM(CC7,BZ7,BW7,BT7,BQ7,BN7,BK7,BH7,BE7,BB7,AY7,AV7)) | G7: =IF(COUNT(CD7,CA7,BX7,BU7,BR7,BO7,BL7,BI7,BF7,BC7,AZ7,AW7)=0,"",SUM(CD7,CA7,BX7,BU7,BR7,BO7,BL7,BI7,BF7,BC7,AZ7,AW7)) | H7: =IF(COUNT(DL7,DI7,DF7,DC7,CZ7,CW7,CT7,CQ7,CN7,CK7,CH7,CE7)=0,"",SUM(DL7,DI7,DF7,DC7,CZ7,CW7,CT7,CQ7,CN7,CK7,CH7,CE7)) | I7: =IF(COUNT(DM7,DJ7,DG7,DD7,DA7,CX7,CU7,CR7,CO7,CL7,CI7,CF7)=0,"",SUM(DM7,DJ7,DG7,DD7,DA7,CX7,CU7,CR7,CO7,CL7,CI7,CF7)) | J7: =IF(COUNT(DN7,DK7,DH7,DE7,DB7,CY7,CV7,CS7,CP7,CM7,CJ7,CG7)=0,"",SUM(DN7,DK7,DH7,DE7,DB7,CY7,CV7,CS7,CP7,CM7,CJ7,CG7)) | K7: =IF(COUNT(K6)=1,K6,"") | L7: =L6 | M7: =M6 | N7: =IF(COUNT(N6)=1,N6,"") | O7: =O6 | P7: =P6 | Q7: =IF(COUNT(Q6)=1,Q6,"") | R7: =R6 | S7: =S6 | T7: =IF(COUNT(T6)=1,T6,"") | U7: =U6 | V7: =V6 | W7: =IF(COUNT(W6)=1,W6,"") | X7: =X6 | Y7: =Y6 | Z7: =IF(COUNT(Z6)=1,Z6,"") | AA7: =AA6 | AB7: =AB6 | AC7: =IF(COUNT(AC6)=1,AC6,"") | AD7: =AD6 | AE7: =AE6 | AF7: =IF(COUNT(AF6)=1,AF6,"") | AG7: =AG6 | AH7: =AH6 | AI7: =IF(COUNT(AI6)=1,AI6,"") | AJ7: =AJ6 | AK7: =AK6 | AL7: =IF(COUNT(AL6)=1,AL6,"") | AM7: =AM6 | AN7: =AN6 | AO7: =IF(COUNT(AO6)=1,AO6,"") | AP7: =AP6 | AQ7: =AQ6 | AR7: =IF(COUNT(AR6)=1,AR6,"") | AS7: =AS6 | AT7: =AT6 | AU7: =IF(COUNT(AU6)=1,AU6,"") | AV7: =AV6 | AW7: =AW6 | AX7: =IF(COUNT(AX6)=1,AX6,"") | AY7: =AY6 | AZ7: =AZ6 | BA7: =IF(COUNT(BA6)=1,BA6,"") | BB7: =BB6 | BC7: =BC6 | BD7: =IF(COUNT(BD6)=1,BD6,"") | BE7: =BE6 | BF7: =BF6 | BG7: =IF(COUNT(BG6)=1,BG6,"") | BH7: =BH6 | BI7: =BI6 | BJ7: =IF(COUNT(BJ6)=1,BJ6,"") | BK7: =BK6 | BL7: =BL6 | BM7: =IF(COUNT(BM6)=1,BM6,"") | BN7: =BN6 | BO7: =BO6 | BP7: =IF(COUNT(BP6)=1,BP6,"") | BQ7: =BQ6 | BR7: =BR6 | BS7: =IF(COUNT(BS6)=1,BS6,"") | BT7: =BT6 | BU7: =BU6 | BV7: =IF(COUNT(BV6)=1,BV6,"") | BW7: =BW6 | BX7: =BX6 | BY7: =IF(COUNT(BY6)=1,BY6,"") | BZ7: =BZ6 | CA7: =CA6 | CB7: =IF(COUNT(CB6)=1,CB6,"") | CC7: =CC6 | CD7: =CD6 | CE7: =IF(COUNT(CE6)=1,CE6,"") | CF7: =CF6 | CG7: =CG6 | CH7: =IF(COUNT(CH6)=1,CH6,"") | CI7: =CI6 | CJ7: =CJ6 | CK7: =IF(COUNT(CK6)=1,CK6,"") | CL7: =CL6 | CM7: =CM6 | CN7: =IF(COUNT(CN6)=1,CN6,"") | CO7: =CO6 | CP7: =CP6 | CQ7: =IF(COUNT(CQ6)=1,CQ6,"") | CR7: =CR6 | CS7: =CS6 | CT7: =IF(COUNT(CT6)=1,CT6,"") | CU7: =CU6 | CV7: =CV6 | CW7: =IF(COUNT(CW6)=1,CW6,"") | CX7: =CX6 | CY7: =CY6 | CZ7: =IF(COUNT(CZ6)=1,CZ6,"") | DA7: =DA6 | DB7: =DB6 | DC7: =IF(COUNT(DC6)=1,DC6,"") | DD7: =DD6 | DE7: =DE6 | DF7: =IF(COUNT(DF6)=1,DF6,"") | DG7: =DG6 | DH7: =DH6 | DI7: =IF(COUNT(DI6)=1,DI6,"") | DJ7: =DJ6 | DK7: =DK6 | DL7: =IF(COUNT(DL6)=1,DL6,"") | DM7: =DM6 | DN7: =DN6
A8: Gross Profit | B8: =IF(COUNT(AR8,AO8,AL8,AI8,AF8,AC8,Z8,W8,T8,Q8,N8,K8)=0,"",SUM(AR8,AO8,AL8,AI8,AF8,AC8,Z8,W8,T8,Q8,N8,K8)) | C8: =IF(COUNT(AS8,AP8,AM8,AJ8,AG8,AD8,AA8,X8,U8,R8,O8,L8)=0,"",SUM(AS8,AP8,AM8,AJ8,AG8,AD8,AA8,X8,U8,R8,O8,L8)) | D8: =IF(COUNT(AT8,AQ8,AN8,AK8,AH8,AE8,AB8,Y8,V8,S8,P8,M8)=0,"",SUM(AT8,AQ8,AN8,AK8,AH8,AE8,AB8,Y8,V8,S8,P8,M8)) | E8: =IF(COUNT(CB8,BY8,BV8,BS8,BP8,BM8,BJ8,BG8,BD8,BA8,AX8,AU8)=0,"",SUM(CB8,BY8,BV8,BS8,BP8,BM8,BJ8,BG8,BD8,BA8,AX8,AU8)) | F8: =IF(COUNT(CC8,BZ8,BW8,BT8,BQ8,BN8,BK8,BH8,BE8,BB8,AY8,AV8)=0,"",SUM(CC8,BZ8,BW8,BT8,BQ8,BN8,BK8,BH8,BE8,BB8,AY8,AV8)) | G8: =IF(COUNT(CD8,CA8,BX8,BU8,BR8,BO8,BL8,BI8,BF8,BC8,AZ8,AW8)=0,"",SUM(CD8,CA8,BX8,BU8,BR8,BO8,BL8,BI8,BF8,BC8,AZ8,AW8)) | H8: =IF(COUNT(DL8,DI8,DF8,DC8,CZ8,CW8,CT8,CQ8,CN8,CK8,CH8,CE8)=0,"",SUM(DL8,DI8,DF8,DC8,CZ8,CW8,CT8,CQ8,CN8,CK8,CH8,CE8)) | I8: =IF(COUNT(DM8,DJ8,DG8,DD8,DA8,CX8,CU8,CR8,CO8,CL8,CI8,CF8)=0,"",SUM(DM8,DJ8,DG8,DD8,DA8,CX8,CU8,CR8,CO8,CL8,CI8,CF8)) | J8: =IF(COUNT(DN8,DK8,DH8,DE8,DB8,CY8,CV8,CS8,CP8,CM8,CJ8,CG8)=0,"",SUM(DN8,DK8,DH8,DE8,DB8,CY8,CV8,CS8,CP8,CM8,CJ8,CG8)) | K8: =IF(COUNT(K7,'Engineering'!K11,'Support'!K25)=3,K7-('Engineering'!K11+'Support'!K25),"") | L8: =L7-('Engineering'!L11+'Support'!L25) | M8: =M7-('Engineering'!M11+'Support'!M25) | N8: =IF(COUNT(N7,'Engineering'!N11,'Support'!N25)=3,N7-('Engineering'!N11+'Support'!N25),"") | O8: =O7-('Engineering'!O11+'Support'!O25) | P8: =P7-('Engineering'!P11+'Support'!P25) | Q8: =IF(COUNT(Q7,'Engineering'!Q11,'Support'!Q25)=3,Q7-('Engineering'!Q11+'Support'!Q25),"") | R8: =R7-('Engineering'!R11+'Support'!R25) | S8: =S7-('Engineering'!S11+'Support'!S25) | T8: =IF(COUNT(T7,'Engineering'!T11,'Support'!T25)=3,T7-('Engineering'!T11+'Support'!T25),"") | U8: =U7-('Engineering'!U11+'Support'!U25) | V8: =V7-('Engineering'!V11+'Support'!V25) | W8: =IF(COUNT(W7,'Engineering'!W11,'Support'!W25)=3,W7-('Engineering'!W11+'Support'!W25),"") | X8: =X7-('Engineering'!X11+'Support'!X25) | Y8: =Y7-('Engineering'!Y11+'Support'!Y25) | Z8: =IF(COUNT(Z7,'Engineering'!Z11,'Support'!Z25)=3,Z7-('Engineering'!Z11+'Support'!Z25),"") | AA8: =AA7-('Engineering'!AA11+'Support'!AA25) | AB8: =AB7-('Engineering'!AB11+'Support'!AB25) | AC8: =IF(COUNT(AC7,'Engineering'!AC11,'Support'!AC25)=3,AC7-('Engineering'!AC11+'Support'!AC25),"") | AD8: =AD7-('Engineering'!AD11+'Support'!AD25) | AE8: =AE7-('Engineering'!AE11+'Support'!AE25) | AF8: =IF(COUNT(AF7,'Engineering'!AF11,'Support'!AF25)=3,AF7-('Engineering'!AF11+'Support'!AF25),"") | AG8: =AG7-('Engineering'!AG11+'Support'!AG25) | AH8: =AH7-('Engineering'!AH11+'Support'!AH25) | AI8: =IF(COUNT(AI7,'Engineering'!AI11,'Support'!AI25)=3,AI7-('Engineering'!AI11+'Support'!AI25),"") | AJ8: =AJ7-('Engineering'!AJ11+'Support'!AJ25) | AK8: =AK7-('Engineering'!AK11+'Support'!AK25) | AL8: =IF(COUNT(AL7,'Engineering'!AL11,'Support'!AL25)=3,AL7-('Engineering'!AL11+'Support'!AL25),"") | AM8: =AM7-('Engineering'!AM11+'Support'!AM25) | AN8: =AN7-('Engineering'!AN11+'Support'!AN25) | AO8: =IF(COUNT(AO7,'Engineering'!AO11,'Support'!AO25)=3,AO7-('Engineering'!AO11+'Support'!AO25),"") | AP8: =AP7-('Engineering'!AP11+'Support'!AP25) | AQ8: =AQ7-('Engineering'!AQ11+'Support'!AQ25) | AR8: =IF(COUNT(AR7,'Engineering'!AR11,'Support'!AR25)=3,AR7-('Engineering'!AR11+'Support'!AR25),"") | AS8: =AS7-('Engineering'!AS11+'Support'!AS25) | AT8: =AT7-('Engineering'!AT11+'Support'!AT25) | AU8: =IF(COUNT(AU7,'Engineering'!AU11,'Support'!AU25)=3,AU7-('Engineering'!AU11+'Support'!AU25),"") | AV8: =AV7-('Engineering'!AV11+'Support'!AV25) | AW8: =AW7-('Engineering'!AW11+'Support'!AW25) | AX8: =IF(COUNT(AX7,'Engineering'!AX11,'Support'!AX25)=3,AX7-('Engineering'!AX11+'Support'!AX25),"") | AY8: =AY7-('Engineering'!AY11+'Support'!AY25) | AZ8: =AZ7-('Engineering'!AZ11+'Support'!AZ25) | BA8: =IF(COUNT(BA7,'Engineering'!BA11,'Support'!BA25)=3,BA7-('Engineering'!BA11+'Support'!BA25),"") | BB8: =BB7-('Engineering'!BB11+'Support'!BB25) | BC8: =BC7-('Engineering'!BC11+'Support'!BC25) | BD8: =IF(COUNT(BD7,'Engineering'!BD11,'Support'!BD25)=3,BD7-('Engineering'!BD11+'Support'!BD25),"") | BE8: =BE7-('Engineering'!BE11+'Support'!BE25) | BF8: =BF7-('Engineering'!BF11+'Support'!BF25) | BG8: =IF(COUNT(BG7,'Engineering'!BG11,'Support'!BG25)=3,BG7-('Engineering'!BG11+'Support'!BG25),"") | BH8: =BH7-('Engineering'!BH11+'Support'!BH25) | BI8: =BI7-('Engineering'!BI11+'Support'!BI25) | BJ8: =IF(COUNT(BJ7,'Engineering'!BJ11,'Support'!BJ25)=3,BJ7-('Engineering'!BJ11+'Support'!BJ25),"") | BK8: =BK7-('Engineering'!BK11+'Support'!BK25) | BL8: =BL7-('Engineering'!BL11+'Support'!BL25) | BM8: =IF(COUNT(BM7,'Engineering'!BM11,'Support'!BM25)=3,BM7-('Engineering'!BM11+'Support'!BM25),"") | BN8: =BN7-('Engineering'!BN11+'Support'!BN25) | BO8: =BO7-('Engineering'!BO11+'Support'!BO25) | BP8: =IF(COUNT(BP7,'Engineering'!BP11,'Support'!BP25)=3,BP7-('Engineering'!BP11+'Support'!BP25),"") | BQ8: =BQ7-('Engineering'!BQ11+'Support'!BQ25) | BR8: =BR7-('Engineering'!BR11+'Support'!BR25) | BS8: =IF(COUNT(BS7,'Engineering'!BS11,'Support'!BS25)=3,BS7-('Engineering'!BS11+'Support'!BS25),"") | BT8: =BT7-('Engineering'!BT11+'Support'!BT25) | BU8: =BU7-('Engineering'!BU11+'Support'!BU25) | BV8: =IF(COUNT(BV7,'Engineering'!BV11,'Support'!BV25)=3,BV7-('Engineering'!BV11+'Support'!BV25),"") | BW8: =BW7-('Engineering'!BW11+'Support'!BW25) | BX8: =BX7-('Engineering'!BX11+'Support'!BX25) | BY8: =IF(COUNT(BY7,'Engineering'!BY11,'Support'!BY25)=3,BY7-('Engineering'!BY11+'Support'!BY25),"") | BZ8: =BZ7-('Engineering'!BZ11+'Support'!BZ25) | CA8: =CA7-('Engineering'!CA11+'Support'!CA25) | CB8: =IF(COUNT(CB7,'Engineering'!CB11,'Support'!CB25)=3,CB7-('Engineering'!CB11+'Support'!CB25),"") | CC8: =CC7-('Engineering'!CC11+'Support'!CC25) | CD8: =CD7-('Engineering'!CD11+'Support'!CD25) | CE8: =IF(COUNT(CE7,'Engineering'!CE11,'Support'!CE25)=3,CE7-('Engineering'!CE11+'Support'!CE25),"") | CF8: =CF7-('Engineering'!CF11+'Support'!CF25) | CG8: =CG7-('Engineering'!CG11+'Support'!CG25) | CH8: =IF(COUNT(CH7,'Engineering'!CH11,'Support'!CH25)=3,CH7-('Engineering'!CH11+'Support'!CH25),"") | CI8: =CI7-('Engineering'!CI11+'Support'!CI25) | CJ8: =CJ7-('Engineering'!CJ11+'Support'!CJ25) | CK8: =IF(COUNT(CK7,'Engineering'!CK11,'Support'!CK25)=3,CK7-('Engineering'!CK11+'Support'!CK25),"") | CL8: =CL7-('Engineering'!CL11+'Support'!CL25) | CM8: =CM7-('Engineering'!CM11+'Support'!CM25) | CN8: =IF(COUNT(CN7,'Engineering'!CN11,'Support'!CN25)=3,CN7-('Engineering'!CN11+'Support'!CN25),"") | CO8: =CO7-('Engineering'!CO11+'Support'!CO25) | CP8: =CP7-('Engineering'!CP11+'Support'!CP25) | CQ8: =IF(COUNT(CQ7,'Engineering'!CQ11,'Support'!CQ25)=3,CQ7-('Engineering'!CQ11+'Support'!CQ25),"") | CR8: =CR7-('Engineering'!CR11+'Support'!CR25) | CS8: =CS7-('Engineering'!CS11+'Support'!CS25) | CT8: =IF(COUNT(CT7,'Engineering'!CT11,'Support'!CT25)=3,CT7-('Engineering'!CT11+'Support'!CT25),"") | CU8: =CU7-('Engineering'!CU11+'Support'!CU25) | CV8: =CV7-('Engineering'!CV11+'Support'!CV25) | CW8: =IF(COUNT(CW7,'Engineering'!CW11,'Support'!CW25)=3,CW7-('Engineering'!CW11+'Support'!CW25),"") | CX8: =CX7-('Engineering'!CX11+'Support'!CX25) | CY8: =CY7-('Engineering'!CY11+'Support'!CY25) | CZ8: =IF(COUNT(CZ7,'Engineering'!CZ11,'Support'!CZ25)=3,CZ7-('Engineering'!CZ11+'Support'!CZ25),"") | DA8: =DA7-('Engineering'!DA11+'Support'!DA25) | DB8: =DB7-('Engineering'!DB11+'Support'!DB25) | DC8: =IF(COUNT(DC7,'Engineering'!DC11,'Support'!DC25)=3,DC7-('Engineering'!DC11+'Support'!DC25),"") | DD8: =DD7-('Engineering'!DD11+'Support'!DD25) | DE8: =DE7-('Engineering'!DE11+'Support'!DE25) | DF8: =IF(COUNT(DF7,'Engineering'!DF11,'Support'!DF25)=3,DF7-('Engineering'!DF11+'Support'!DF25),"") | DG8: =DG7-('Engineering'!DG11+'Support'!DG25) | DH8: =DH7-('Engineering'!DH11+'Support'!DH25) | DI8: =IF(COUNT(DI7,'Engineering'!DI11,'Support'!DI25)=3,DI7-('Engineering'!DI11+'Support'!DI25),"") | DJ8: =DJ7-('Engineering'!DJ11+'Support'!DJ25) | DK8: =DK7-('Engineering'!DK11+'Support'!DK25) | DL8: =IF(COUNT(DL7,'Engineering'!DL11,'Support'!DL25)=3,DL7-('Engineering'!DL11+'Support'!DL25),"") | DM8: =DM7-('Engineering'!DM11+'Support'!DM25) | DN8: =DN7-('Engineering'!DN11+'Support'!DN25)
A9: Gross Margin | B9: =IF(N(B7)=0,"",B8/B7) | C9: =IF(N(C7)=0,"",C8/C7) | D9: =IF(N(D7)=0,"",D8/D7) | E9: =IF(N(E7)=0,"",E8/E7) | F9: =IF(N(F7)=0,"",F8/F7) | G9: =IF(N(G7)=0,"",G8/G7) | H9: =IF(N(H7)=0,"",H8/H7) | I9: =IF(N(I7)=0,"",I8/I7) | J9: =IF(N(J7)=0,"",J8/J7) | K9: =IF(COUNT(K7,K8)=2,IF(K7=0,"",K8/K7),"") | L9: =IF(L7=0,"",L8/L7) | M9: =IF(M7=0,"",M8/M7) | N9: =IF(COUNT(N7,N8)=2,IF(N7=0,"",N8/N7),"") | O9: =IF(O7=0,"",O8/O7) | P9: =IF(P7=0,"",P8/P7) | Q9: =IF(COUNT(Q7,Q8)=2,IF(Q7=0,"",Q8/Q7),"") | R9: =IF(R7=0,"",R8/R7) | S9: =IF(S7=0,"",S8/S7) | T9: =IF(COUNT(T7,T8)=2,IF(T7=0,"",T8/T7),"") | U9: =IF(U7=0,"",U8/U7) | V9: =IF(V7=0,"",V8/V7) | W9: =IF(COUNT(W7,W8)=2,IF(W7=0,"",W8/W7),"") | X9: =IF(X7=0,"",X8/X7) | Y9: =IF(Y7=0,"",Y8/Y7) | Z9: =IF(COUNT(Z7,Z8)=2,IF(Z7=0,"",Z8/Z7),"") | AA9: =IF(AA7=0,"",AA8/AA7) | AB9: =IF(AB7=0,"",AB8/AB7) | AC9: =IF(COUNT(AC7,AC8)=2,IF(AC7=0,"",AC8/AC7),"") | AD9: =IF(AD7=0,"",AD8/AD7) | AE9: =IF(AE7=0,"",AE8/AE7) | AF9: =IF(COUNT(AF7,AF8)=2,IF(AF7=0,"",AF8/AF7),"") | AG9: =IF(AG7=0,"",AG8/AG7) | AH9: =IF(AH7=0,"",AH8/AH7) | AI9: =IF(COUNT(AI7,AI8)=2,IF(AI7=0,"",AI8/AI7),"") | AJ9: =IF(AJ7=0,"",AJ8/AJ7) | AK9: =IF(AK7=0,"",AK8/AK7) | AL9: =IF(COUNT(AL7,AL8)=2,IF(AL7=0,"",AL8/AL7),"") | AM9: =IF(AM7=0,"",AM8/AM7) | AN9: =IF(AN7=0,"",AN8/AN7) | AO9: =IF(COUNT(AO7,AO8)=2,IF(AO7=0,"",AO8/AO7),"") | AP9: =IF(AP7=0,"",AP8/AP7) | AQ9: =IF(AQ7=0,"",AQ8/AQ7) | AR9: =IF(COUNT(AR7,AR8)=2,IF(AR7=0,"",AR8/AR7),"") | AS9: =IF(AS7=0,"",AS8/AS7) | AT9: =IF(AT7=0,"",AT8/AT7) | AU9: =IF(COUNT(AU7,AU8)=2,IF(AU7=0,"",AU8/AU7),"") | AV9: =IF(AV7=0,"",AV8/AV7) | AW9: =IF(AW7=0,"",AW8/AW7) | AX9: =IF(COUNT(AX7,AX8)=2,IF(AX7=0,"",AX8/AX7),"") | AY9: =IF(AY7=0,"",AY8/AY7) | AZ9: =IF(AZ7=0,"",AZ8/AZ7) | BA9: =IF(COUNT(BA7,BA8)=2,IF(BA7=0,"",BA8/BA7),"") | BB9: =IF(BB7=0,"",BB8/BB7) | BC9: =IF(BC7=0,"",BC8/BC7) | BD9: =IF(COUNT(BD7,BD8)=2,IF(BD7=0,"",BD8/BD7),"") | BE9: =IF(BE7=0,"",BE8/BE7) | BF9: =IF(BF7=0,"",BF8/BF7) | BG9: =IF(COUNT(BG7,BG8)=2,IF(BG7=0,"",BG8/BG7),"") | BH9: =IF(BH7=0,"",BH8/BH7) | BI9: =IF(BI7=0,"",BI8/BI7) | BJ9: =IF(COUNT(BJ7,BJ8)=2,IF(BJ7=0,"",BJ8/BJ7),"") | BK9: =IF(BK7=0,"",BK8/BK7) | BL9: =IF(BL7=0,"",BL8/BL7) | BM9: =IF(COUNT(BM7,BM8)=2,IF(BM7=0,"",BM8/BM7),"") | BN9: =IF(BN7=0,"",BN8/BN7) | BO9: =IF(BO7=0,"",BO8/BO7) | BP9: =IF(COUNT(BP7,BP8)=2,IF(BP7=0,"",BP8/BP7),"") | BQ9: =IF(BQ7=0,"",BQ8/BQ7) | BR9: =IF(BR7=0,"",BR8/BR7) | BS9: =IF(COUNT(BS7,BS8)=2,IF(BS7=0,"",BS8/BS7),"") | BT9: =IF(BT7=0,"",BT8/BT7) | BU9: =IF(BU7=0,"",BU8/BU7) | BV9: =IF(COUNT(BV7,BV8)=2,IF(BV7=0,"",BV8/BV7),"") | BW9: =IF(BW7=0,"",BW8/BW7) | BX9: =IF(BX7=0,"",BX8/BX7) | BY9: =IF(COUNT(BY7,BY8)=2,IF(BY7=0,"",BY8/BY7),"") | BZ9: =IF(BZ7=0,"",BZ8/BZ7) | CA9: =IF(CA7=0,"",CA8/CA7) | CB9: =IF(COUNT(CB7,CB8)=2,IF(CB7=0,"",CB8/CB7),"") | CC9: =IF(CC7=0,"",CC8/CC7) | CD9: =IF(CD7=0,"",CD8/CD7) | CE9: =IF(COUNT(CE7,CE8)=2,IF(CE7=0,"",CE8/CE7),"") | CF9: =IF(CF7=0,"",CF8/CF7) | CG9: =IF(CG7=0,"",CG8/CG7) | CH9: =IF(COUNT(CH7,CH8)=2,IF(CH7=0,"",CH8/CH7),"") | CI9: =IF(CI7=0,"",CI8/CI7) | CJ9: =IF(CJ7=0,"",CJ8/CJ7) | CK9: =IF(COUNT(CK7,CK8)=2,IF(CK7=0,"",CK8/CK7),"") | CL9: =IF(CL7=0,"",CL8/CL7) | CM9: =IF(CM7=0,"",CM8/CM7) | CN9: =IF(COUNT(CN7,CN8)=2,IF(CN7=0,"",CN8/CN7),"") | CO9: =IF(CO7=0,"",CO8/CO7) | CP9: =IF(CP7=0,"",CP8/CP7) | CQ9: =IF(COUNT(CQ7,CQ8)=2,IF(CQ7=0,"",CQ8/CQ7),"") | CR9: =IF(CR7=0,"",CR8/CR7) | CS9: =IF(CS7=0,"",CS8/CS7) | CT9: =IF(COUNT(CT7,CT8)=2,IF(CT7=0,"",CT8/CT7),"") | CU9: =IF(CU7=0,"",CU8/CU7) | CV9: =IF(CV7=0,"",CV8/CV7) | CW9: =IF(COUNT(CW7,CW8)=2,IF(CW7=0,"",CW8/CW7),"") | CX9: =IF(CX7=0,"",CX8/CX7) | CY9: =IF(CY7=0,"",CY8/CY7) | CZ9: =IF(COUNT(CZ7,CZ8)=2,IF(CZ7=0,"",CZ8/CZ7),"") | DA9: =IF(DA7=0,"",DA8/DA7) | DB9: =IF(DB7=0,"",DB8/DB7) | DC9: =IF(COUNT(DC7,DC8)=2,IF(DC7=0,"",DC8/DC7),"") | DD9: =IF(DD7=0,"",DD8/DD7) | DE9: =IF(DE7=0,"",DE8/DE7) | DF9: =IF(COUNT(DF7,DF8)=2,IF(DF7=0,"",DF8/DF7),"") | DG9: =IF(DG7=0,"",DG8/DG7) | DH9: =IF(DH7=0,"",DH8/DH7) | DI9: =IF(COUNT(DI7,DI8)=2,IF(DI7=0,"",DI8/DI7),"") | DJ9: =IF(DJ7=0,"",DJ8/DJ7) | DK9: =IF(DK7=0,"",DK8/DK7) | DL9: =IF(COUNT(DL7,DL8)=2,IF(DL7=0,"",DL8/DL7),"") | DM9: =IF(DM7=0,"",DM8/DM7) | DN9: =IF(DN7=0,"",DN8/DN7)
A10: Operating Expenses | B10: =IF(COUNT(AR10,AO10,AL10,AI10,AF10,AC10,Z10,W10,T10,Q10,N10,K10)=0,"",SUM(AR10,AO10,AL10,AI10,AF10,AC10,Z10,W10,T10,Q10,N10,K10)) | C10: =IF(COUNT(AS10,AP10,AM10,AJ10,AG10,AD10,AA10,X10,U10,R10,O10,L10)=0,"",SUM(AS10,AP10,AM10,AJ10,AG10,AD10,AA10,X10,U10,R10,O10,L10)) | D10: =IF(COUNT(AT10,AQ10,AN10,AK10,AH10,AE10,AB10,Y10,V10,S10,P10,M10)=0,"",SUM(AT10,AQ10,AN10,AK10,AH10,AE10,AB10,Y10,V10,S10,P10,M10)) | E10: =IF(COUNT(CB10,BY10,BV10,BS10,BP10,BM10,BJ10,BG10,BD10,BA10,AX10,AU10)=0,"",SUM(CB10,BY10,BV10,BS10,BP10,BM10,BJ10,BG10,BD10,BA10,AX10,AU10)) | F10: =IF(COUNT(CC10,BZ10,BW10,BT10,BQ10,BN10,BK10,BH10,BE10,BB10,AY10,AV10)=0,"",SUM(CC10,BZ10,BW10,BT10,BQ10,BN10,BK10,BH10,BE10,BB10,AY10,AV10)) | G10: =IF(COUNT(CD10,CA10,BX10,BU10,BR10,BO10,BL10,BI10,BF10,BC10,AZ10,AW10)=0,"",SUM(CD10,CA10,BX10,BU10,BR10,BO10,BL10,BI10,BF10,BC10,AZ10,AW10)) | H10: =IF(COUNT(DL10,DI10,DF10,DC10,CZ10,CW10,CT10,CQ10,CN10,CK10,CH10,CE10)=0,"",SUM(DL10,DI10,DF10,DC10,CZ10,CW10,CT10,CQ10,CN10,CK10,CH10,CE10)) | I10: =IF(COUNT(DM10,DJ10,DG10,DD10,DA10,CX10,CU10,CR10,CO10,CL10,CI10,CF10)=0,"",SUM(DM10,DJ10,DG10,DD10,DA10,CX10,CU10,CR10,CO10,CL10,CI10,CF10)) | J10: =IF(COUNT(DN10,DK10,DH10,DE10,DB10,CY10,CV10,CS10,CP10,CM10,CJ10,CG10)=0,"",SUM(DN10,DK10,DH10,DE10,DB10,CY10,CV10,CS10,CP10,CM10,CJ10,CG10)) | K10: =IF(COUNT('Marketing'!K28,'Sales'!K24,'Customer Success'!K33,'Engineering'!K27,'Finance'!K38,'Engineering'!K11)=6,'Marketing'!K28+'Sales'!K24+'Customer Success'!K33+'Engineering'!K27-'Engineering'!K11+'Finance'!K38,"") | L10: ='Marketing'!L28+'Sales'!L24+'Customer Success'!L33+'Engineering'!L27-'Engineering'!L11+'Finance'!L38 | M10: ='Marketing'!M28+'Sales'!M24+'Customer Success'!M33+'Engineering'!M27-'Engineering'!M11+'Finance'!M38 | N10: =IF(COUNT('Marketing'!N28,'Sales'!N24,'Customer Success'!N33,'Engineering'!N27,'Finance'!N38,'Engineering'!N11)=6,'Marketing'!N28+'Sales'!N24+'Customer Success'!N33+'Engineering'!N27-'Engineering'!N11+'Finance'!N38,"") | O10: ='Marketing'!O28+'Sales'!O24+'Customer Success'!O33+'Engineering'!O27-'Engineering'!O11+'Finance'!O38 | P10: ='Marketing'!P28+'Sales'!P24+'Customer Success'!P33+'Engineering'!P27-'Engineering'!P11+'Finance'!P38 | Q10: =IF(COUNT('Marketing'!Q28,'Sales'!Q24,'Customer Success'!Q33,'Engineering'!Q27,'Finance'!Q38,'Engineering'!Q11)=6,'Marketing'!Q28+'Sales'!Q24+'Customer Success'!Q33+'Engineering'!Q27-'Engineering'!Q11+'Finance'!Q38,"") | R10: ='Marketing'!R28+'Sales'!R24+'Customer Success'!R33+'Engineering'!R27-'Engineering'!R11+'Finance'!R38 | S10: ='Marketing'!S28+'Sales'!S24+'Customer Success'!S33+'Engineering'!S27-'Engineering'!S11+'Finance'!S38 | T10: =IF(COUNT('Marketing'!T28,'Sales'!T24,'Customer Success'!T33,'Engineering'!T27,'Finance'!T38,'Engineering'!T11)=6,'Marketing'!T28+'Sales'!T24+'Customer Success'!T33+'Engineering'!T27-'Engineering'!T11+'Finance'!T38,"") | U10: ='Marketing'!U28+'Sales'!U24+'Customer Success'!U33+'Engineering'!U27-'Engineering'!U11+'Finance'!U38 | V10: ='Marketing'!V28+'Sales'!V24+'Customer Success'!V33+'Engineering'!V27-'Engineering'!V11+'Finance'!V38 | W10: =IF(COUNT('Marketing'!W28,'Sales'!W24,'Customer Success'!W33,'Engineering'!W27,'Finance'!W38,'Engineering'!W11)=6,'Marketing'!W28+'Sales'!W24+'Customer Success'!W33+'Engineering'!W27-'Engineering'!W11+'Finance'!W38,"") | X10: ='Marketing'!X28+'Sales'!X24+'Customer Success'!X33+'Engineering'!X27-'Engineering'!X11+'Finance'!X38 | Y10: ='Marketing'!Y28+'Sales'!Y24+'Customer Success'!Y33+'Engineering'!Y27-'Engineering'!Y11+'Finance'!Y38 | Z10: =IF(COUNT('Marketing'!Z28,'Sales'!Z24,'Customer Success'!Z33,'Engineering'!Z27,'Finance'!Z38,'Engineering'!Z11)=6,'Marketing'!Z28+'Sales'!Z24+'Customer Success'!Z33+'Engineering'!Z27-'Engineering'!Z11+'Finance'!Z38,"") | AA10: ='Marketing'!AA28+'Sales'!AA24+'Customer Success'!AA33+'Engineering'!AA27-'Engineering'!AA11+'Finance'!AA38 | AB10: ='Marketing'!AB28+'Sales'!AB24+'Customer Success'!AB33+'Engineering'!AB27-'Engineering'!AB11+'Finance'!AB38 | AC10: =IF(COUNT('Marketing'!AC28,'Sales'!AC24,'Customer Success'!AC33,'Engineering'!AC27,'Finance'!AC38,'Engineering'!AC11)=6,'Marketing'!AC28+'Sales'!AC24+'Customer Success'!AC33+'Engineering'!AC27-'Engineering'!AC11+'Finance'!AC38,"") | AD10: ='Marketing'!AD28+'Sales'!AD24+'Customer Success'!AD33+'Engineering'!AD27-'Engineering'!AD11+'Finance'!AD38 | AE10: ='Marketing'!AE28+'Sales'!AE24+'Customer Success'!AE33+'Engineering'!AE27-'Engineering'!AE11+'Finance'!AE38 | AF10: =IF(COUNT('Marketing'!AF28,'Sales'!AF24,'Customer Success'!AF33,'Engineering'!AF27,'Finance'!AF38,'Engineering'!AF11)=6,'Marketing'!AF28+'Sales'!AF24+'Customer Success'!AF33+'Engineering'!AF27-'Engineering'!AF11+'Finance'!AF38,"") | AG10: ='Marketing'!AG28+'Sales'!AG24+'Customer Success'!AG33+'Engineering'!AG27-'Engineering'!AG11+'Finance'!AG38 | AH10: ='Marketing'!AH28+'Sales'!AH24+'Customer Success'!AH33+'Engineering'!AH27-'Engineering'!AH11+'Finance'!AH38 | AI10: =IF(COUNT('Marketing'!AI28,'Sales'!AI24,'Customer Success'!AI33,'Engineering'!AI27,'Finance'!AI38,'Engineering'!AI11)=6,'Marketing'!AI28+'Sales'!AI24+'Customer Success'!AI33+'Engineering'!AI27-'Engineering'!AI11+'Finance'!AI38,"") | AJ10: ='Marketing'!AJ28+'Sales'!AJ24+'Customer Success'!AJ33+'Engineering'!AJ27-'Engineering'!AJ11+'Finance'!AJ38 | AK10: ='Marketing'!AK28+'Sales'!AK24+'Customer Success'!AK33+'Engineering'!AK27-'Engineering'!AK11+'Finance'!AK38 | AL10: =IF(COUNT('Marketing'!AL28,'Sales'!AL24,'Customer Success'!AL33,'Engineering'!AL27,'Finance'!AL38,'Engineering'!AL11)=6,'Marketing'!AL28+'Sales'!AL24+'Customer Success'!AL33+'Engineering'!AL27-'Engineering'!AL11+'Finance'!AL38,"") | AM10: ='Marketing'!AM28+'Sales'!AM24+'Customer Success'!AM33+'Engineering'!AM27-'Engineering'!AM11+'Finance'!AM38 | AN10: ='Marketing'!AN28+'Sales'!AN24+'Customer Success'!AN33+'Engineering'!AN27-'Engineering'!AN11+'Finance'!AN38 | AO10: =IF(COUNT('Marketing'!AO28,'Sales'!AO24,'Customer Success'!AO33,'Engineering'!AO27,'Finance'!AO38,'Engineering'!AO11)=6,'Marketing'!AO28+'Sales'!AO24+'Customer Success'!AO33+'Engineering'!AO27-'Engineering'!AO11+'Finance'!AO38,"") | AP10: ='Marketing'!AP28+'Sales'!AP24+'Customer Success'!AP33+'Engineering'!AP27-'Engineering'!AP11+'Finance'!AP38 | AQ10: ='Marketing'!AQ28+'Sales'!AQ24+'Customer Success'!AQ33+'Engineering'!AQ27-'Engineering'!AQ11+'Finance'!AQ38 | AR10: =IF(COUNT('Marketing'!AR28,'Sales'!AR24,'Customer Success'!AR33,'Engineering'!AR27,'Finance'!AR38,'Engineering'!AR11)=6,'Marketing'!AR28+'Sales'!AR24+'Customer Success'!AR33+'Engineering'!AR27-'Engineering'!AR11+'Finance'!AR38,"") | AS10: ='Marketing'!AS28+'Sales'!AS24+'Customer Success'!AS33+'Engineering'!AS27-'Engineering'!AS11+'Finance'!AS38 | AT10: ='Marketing'!AT28+'Sales'!AT24+'Customer Success'!AT33+'Engineering'!AT27-'Engineering'!AT11+'Finance'!AT38 | AU10: =IF(COUNT('Marketing'!AU28,'Sales'!AU24,'Customer Success'!AU33,'Engineering'!AU27,'Finance'!AU38,'Engineering'!AU11)=6,'Marketing'!AU28+'Sales'!AU24+'Customer Success'!AU33+'Engineering'!AU27-'Engineering'!AU11+'Finance'!AU38,"") | AV10: ='Marketing'!AV28+'Sales'!AV24+'Customer Success'!AV33+'Engineering'!AV27-'Engineering'!AV11+'Finance'!AV38 | AW10: ='Marketing'!AW28+'Sales'!AW24+'Customer Success'!AW33+'Engineering'!AW27-'Engineering'!AW11+'Finance'!AW38 | AX10: =IF(COUNT('Marketing'!AX28,'Sales'!AX24,'Customer Success'!AX33,'Engineering'!AX27,'Finance'!AX38,'Engineering'!AX11)=6,'Marketing'!AX28+'Sales'!AX24+'Customer Success'!AX33+'Engineering'!AX27-'Engineering'!AX11+'Finance'!AX38,"") | AY10: ='Marketing'!AY28+'Sales'!AY24+'Customer Success'!AY33+'Engineering'!AY27-'Engineering'!AY11+'Finance'!AY38 | AZ10: ='Marketing'!AZ28+'Sales'!AZ24+'Customer Success'!AZ33+'Engineering'!AZ27-'Engineering'!AZ11+'Finance'!AZ38 | BA10: =IF(COUNT('Marketing'!BA28,'Sales'!BA24,'Customer Success'!BA33,'Engineering'!BA27,'Finance'!BA38,'Engineering'!BA11)=6,'Marketing'!BA28+'Sales'!BA24+'Customer Success'!BA33+'Engineering'!BA27-'Engineering'!BA11+'Finance'!BA38,"") | BB10: ='Marketing'!BB28+'Sales'!BB24+'Customer Success'!BB33+'Engineering'!BB27-'Engineering'!BB11+'Finance'!BB38 | BC10: ='Marketing'!BC28+'Sales'!BC24+'Customer Success'!BC33+'Engineering'!BC27-'Engineering'!BC11+'Finance'!BC38 | BD10: =IF(COUNT('Marketing'!BD28,'Sales'!BD24,'Customer Success'!BD33,'Engineering'!BD27,'Finance'!BD38,'Engineering'!BD11)=6,'Marketing'!BD28+'Sales'!BD24+'Customer Success'!BD33+'Engineering'!BD27-'Engineering'!BD11+'Finance'!BD38,"") | BE10: ='Marketing'!BE28+'Sales'!BE24+'Customer Success'!BE33+'Engineering'!BE27-'Engineering'!BE11+'Finance'!BE38 | BF10: ='Marketing'!BF28+'Sales'!BF24+'Customer Success'!BF33+'Engineering'!BF27-'Engineering'!BF11+'Finance'!BF38 | BG10: =IF(COUNT('Marketing'!BG28,'Sales'!BG24,'Customer Success'!BG33,'Engineering'!BG27,'Finance'!BG38,'Engineering'!BG11)=6,'Marketing'!BG28+'Sales'!BG24+'Customer Success'!BG33+'Engineering'!BG27-'Engineering'!BG11+'Finance'!BG38,"") | BH10: ='Marketing'!BH28+'Sales'!BH24+'Customer Success'!BH33+'Engineering'!BH27-'Engineering'!BH11+'Finance'!BH38 | BI10: ='Marketing'!BI28+'Sales'!BI24+'Customer Success'!BI33+'Engineering'!BI27-'Engineering'!BI11+'Finance'!BI38 | BJ10: =IF(COUNT('Marketing'!BJ28,'Sales'!BJ24,'Customer Success'!BJ33,'Engineering'!BJ27,'Finance'!BJ38,'Engineering'!BJ11)=6,'Marketing'!BJ28+'Sales'!BJ24+'Customer Success'!BJ33+'Engineering'!BJ27-'Engineering'!BJ11+'Finance'!BJ38,"") | BK10: ='Marketing'!BK28+'Sales'!BK24+'Customer Success'!BK33+'Engineering'!BK27-'Engineering'!BK11+'Finance'!BK38 | BL10: ='Marketing'!BL28+'Sales'!BL24+'Customer Success'!BL33+'Engineering'!BL27-'Engineering'!BL11+'Finance'!BL38 | BM10: =IF(COUNT('Marketing'!BM28,'Sales'!BM24,'Customer Success'!BM33,'Engineering'!BM27,'Finance'!BM38,'Engineering'!BM11)=6,'Marketing'!BM28+'Sales'!BM24+'Customer Success'!BM33+'Engineering'!BM27-'Engineering'!BM11+'Finance'!BM38,"") | BN10: ='Marketing'!BN28+'Sales'!BN24+'Customer Success'!BN33+'Engineering'!BN27-'Engineering'!BN11+'Finance'!BN38 | BO10: ='Marketing'!BO28+'Sales'!BO24+'Customer Success'!BO33+'Engineering'!BO27-'Engineering'!BO11+'Finance'!BO38 | BP10: =IF(COUNT('Marketing'!BP28,'Sales'!BP24,'Customer Success'!BP33,'Engineering'!BP27,'Finance'!BP38,'Engineering'!BP11)=6,'Marketing'!BP28+'Sales'!BP24+'Customer Success'!BP33+'Engineering'!BP27-'Engineering'!BP11+'Finance'!BP38,"") | BQ10: ='Marketing'!BQ28+'Sales'!BQ24+'Customer Success'!BQ33+'Engineering'!BQ27-'Engineering'!BQ11+'Finance'!BQ38 | BR10: ='Marketing'!BR28+'Sales'!BR24+'Customer Success'!BR33+'Engineering'!BR27-'Engineering'!BR11+'Finance'!BR38 | BS10: =IF(COUNT('Marketing'!BS28,'Sales'!BS24,'Customer Success'!BS33,'Engineering'!BS27,'Finance'!BS38,'Engineering'!BS11)=6,'Marketing'!BS28+'Sales'!BS24+'Customer Success'!BS33+'Engineering'!BS27-'Engineering'!BS11+'Finance'!BS38,"") | BT10: ='Marketing'!BT28+'Sales'!BT24+'Customer Success'!BT33+'Engineering'!BT27-'Engineering'!BT11+'Finance'!BT38 | BU10: ='Marketing'!BU28+'Sales'!BU24+'Customer Success'!BU33+'Engineering'!BU27-'Engineering'!BU11+'Finance'!BU38 | BV10: =IF(COUNT('Marketing'!BV28,'Sales'!BV24,'Customer Success'!BV33,'Engineering'!BV27,'Finance'!BV38,'Engineering'!BV11)=6,'Marketing'!BV28+'Sales'!BV24+'Customer Success'!BV33+'Engineering'!BV27-'Engineering'!BV11+'Finance'!BV38,"") | BW10: ='Marketing'!BW28+'Sales'!BW24+'Customer Success'!BW33+'Engineering'!BW27-'Engineering'!BW11+'Finance'!BW38 | BX10: ='Marketing'!BX28+'Sales'!BX24+'Customer Success'!BX33+'Engineering'!BX27-'Engineering'!BX11+'Finance'!BX38 | BY10: =IF(COUNT('Marketing'!BY28,'Sales'!BY24,'Customer Success'!BY33,'Engineering'!BY27,'Finance'!BY38,'Engineering'!BY11)=6,'Marketing'!BY28+'Sales'!BY24+'Customer Success'!BY33+'Engineering'!BY27-'Engineering'!BY11+'Finance'!BY38,"") | BZ10: ='Marketing'!BZ28+'Sales'!BZ24+'Customer Success'!BZ33+'Engineering'!BZ27-'Engineering'!BZ11+'Finance'!BZ38 | CA10: ='Marketing'!CA28+'Sales'!CA24+'Customer Success'!CA33+'Engineering'!CA27-'Engineering'!CA11+'Finance'!CA38 | CB10: =IF(COUNT('Marketing'!CB28,'Sales'!CB24,'Customer Success'!CB33,'Engineering'!CB27,'Finance'!CB38,'Engineering'!CB11)=6,'Marketing'!CB28+'Sales'!CB24+'Customer Success'!CB33+'Engineering'!CB27-'Engineering'!CB11+'Finance'!CB38,"") | CC10: ='Marketing'!CC28+'Sales'!CC24+'Customer Success'!CC33+'Engineering'!CC27-'Engineering'!CC11+'Finance'!CC38 | CD10: ='Marketing'!CD28+'Sales'!CD24+'Customer Success'!CD33+'Engineering'!CD27-'Engineering'!CD11+'Finance'!CD38 | CE10: =IF(COUNT('Marketing'!CE28,'Sales'!CE24,'Customer Success'!CE33,'Engineering'!CE27,'Finance'!CE38,'Engineering'!CE11)=6,'Marketing'!CE28+'Sales'!CE24+'Customer Success'!CE33+'Engineering'!CE27-'Engineering'!CE11+'Finance'!CE38,"") | CF10: ='Marketing'!CF28+'Sales'!CF24+'Customer Success'!CF33+'Engineering'!CF27-'Engineering'!CF11+'Finance'!CF38 | CG10: ='Marketing'!CG28+'Sales'!CG24+'Customer Success'!CG33+'Engineering'!CG27-'Engineering'!CG11+'Finance'!CG38 | CH10: =IF(COUNT('Marketing'!CH28,'Sales'!CH24,'Customer Success'!CH33,'Engineering'!CH27,'Finance'!CH38,'Engineering'!CH11)=6,'Marketing'!CH28+'Sales'!CH24+'Customer Success'!CH33+'Engineering'!CH27-'Engineering'!CH11+'Finance'!CH38,"") | CI10: ='Marketing'!CI28+'Sales'!CI24+'Customer Success'!CI33+'Engineering'!CI27-'Engineering'!CI11+'Finance'!CI38 | CJ10: ='Marketing'!CJ28+'Sales'!CJ24+'Customer Success'!CJ33+'Engineering'!CJ27-'Engineering'!CJ11+'Finance'!CJ38 | CK10: =IF(COUNT('Marketing'!CK28,'Sales'!CK24,'Customer Success'!CK33,'Engineering'!CK27,'Finance'!CK38,'Engineering'!CK11)=6,'Marketing'!CK28+'Sales'!CK24+'Customer Success'!CK33+'Engineering'!CK27-'Engineering'!CK11+'Finance'!CK38,"") | CL10: ='Marketing'!CL28+'Sales'!CL24+'Customer Success'!CL33+'Engineering'!CL27-'Engineering'!CL11+'Finance'!CL38 | CM10: ='Marketing'!CM28+'Sales'!CM24+'Customer Success'!CM33+'Engineering'!CM27-'Engineering'!CM11+'Finance'!CM38 | CN10: =IF(COUNT('Marketing'!CN28,'Sales'!CN24,'Customer Success'!CN33,'Engineering'!CN27,'Finance'!CN38,'Engineering'!CN11)=6,'Marketing'!CN28+'Sales'!CN24+'Customer Success'!CN33+'Engineering'!CN27-'Engineering'!CN11+'Finance'!CN38,"") | CO10: ='Marketing'!CO28+'Sales'!CO24+'Customer Success'!CO33+'Engineering'!CO27-'Engineering'!CO11+'Finance'!CO38 | CP10: ='Marketing'!CP28+'Sales'!CP24+'Customer Success'!CP33+'Engineering'!CP27-'Engineering'!CP11+'Finance'!CP38 | CQ10: =IF(COUNT('Marketing'!CQ28,'Sales'!CQ24,'Customer Success'!CQ33,'Engineering'!CQ27,'Finance'!CQ38,'Engineering'!CQ11)=6,'Marketing'!CQ28+'Sales'!CQ24+'Customer Success'!CQ33+'Engineering'!CQ27-'Engineering'!CQ11+'Finance'!CQ38,"") | CR10: ='Marketing'!CR28+'Sales'!CR24+'Customer Success'!CR33+'Engineering'!CR27-'Engineering'!CR11+'Finance'!CR38 | CS10: ='Marketing'!CS28+'Sales'!CS24+'Customer Success'!CS33+'Engineering'!CS27-'Engineering'!CS11+'Finance'!CS38 | CT10: =IF(COUNT('Marketing'!CT28,'Sales'!CT24,'Customer Success'!CT33,'Engineering'!CT27,'Finance'!CT38,'Engineering'!CT11)=6,'Marketing'!CT28+'Sales'!CT24+'Customer Success'!CT33+'Engineering'!CT27-'Engineering'!CT11+'Finance'!CT38,"") | CU10: ='Marketing'!CU28+'Sales'!CU24+'Customer Success'!CU33+'Engineering'!CU27-'Engineering'!CU11+'Finance'!CU38 | CV10: ='Marketing'!CV28+'Sales'!CV24+'Customer Success'!CV33+'Engineering'!CV27-'Engineering'!CV11+'Finance'!CV38 | CW10: =IF(COUNT('Marketing'!CW28,'Sales'!CW24,'Customer Success'!CW33,'Engineering'!CW27,'Finance'!CW38,'Engineering'!CW11)=6,'Marketing'!CW28+'Sales'!CW24+'Customer Success'!CW33+'Engineering'!CW27-'Engineering'!CW11+'Finance'!CW38,"") | CX10: ='Marketing'!CX28+'Sales'!CX24+'Customer Success'!CX33+'Engineering'!CX27-'Engineering'!CX11+'Finance'!CX38 | CY10: ='Marketing'!CY28+'Sales'!CY24+'Customer Success'!CY33+'Engineering'!CY27-'Engineering'!CY11+'Finance'!CY38 | CZ10: =IF(COUNT('Marketing'!CZ28,'Sales'!CZ24,'Customer Success'!CZ33,'Engineering'!CZ27,'Finance'!CZ38,'Engineering'!CZ11)=6,'Marketing'!CZ28+'Sales'!CZ24+'Customer Success'!CZ33+'Engineering'!CZ27-'Engineering'!CZ11+'Finance'!CZ38,"") | DA10: ='Marketing'!DA28+'Sales'!DA24+'Customer Success'!DA33+'Engineering'!DA27-'Engineering'!DA11+'Finance'!DA38 | DB10: ='Marketing'!DB28+'Sales'!DB24+'Customer Success'!DB33+'Engineering'!DB27-'Engineering'!DB11+'Finance'!DB38 | DC10: =IF(COUNT('Marketing'!DC28,'Sales'!DC24,'Customer Success'!DC33,'Engineering'!DC27,'Finance'!DC38,'Engineering'!DC11)=6,'Marketing'!DC28+'Sales'!DC24+'Customer Success'!DC33+'Engineering'!DC27-'Engineering'!DC11+'Finance'!DC38,"") | DD10: ='Marketing'!DD28+'Sales'!DD24+'Customer Success'!DD33+'Engineering'!DD27-'Engineering'!DD11+'Finance'!DD38 | DE10: ='Marketing'!DE28+'Sales'!DE24+'Customer Success'!DE33+'Engineering'!DE27-'Engineering'!DE11+'Finance'!DE38 | DF10: =IF(COUNT('Marketing'!DF28,'Sales'!DF24,'Customer Success'!DF33,'Engineering'!DF27,'Finance'!DF38,'Engineering'!DF11)=6,'Marketing'!DF28+'Sales'!DF24+'Customer Success'!DF33+'Engineering'!DF27-'Engineering'!DF11+'Finance'!DF38,"") | DG10: ='Marketing'!DG28+'Sales'!DG24+'Customer Success'!DG33+'Engineering'!DG27-'Engineering'!DG11+'Finance'!DG38 | DH10: ='Marketing'!DH28+'Sales'!DH24+'Customer Success'!DH33+'Engineering'!DH27-'Engineering'!DH11+'Finance'!DH38 | DI10: =IF(COUNT('Marketing'!DI28,'Sales'!DI24,'Customer Success'!DI33,'Engineering'!DI27,'Finance'!DI38,'Engineering'!DI11)=6,'Marketing'!DI28+'Sales'!DI24+'Customer Success'!DI33+'Engineering'!DI27-'Engineering'!DI11+'Finance'!DI38,"") | DJ10: ='Marketing'!DJ28+'Sales'!DJ24+'Customer Success'!DJ33+'Engineering'!DJ27-'Engineering'!DJ11+'Finance'!DJ38 | DK10: ='Marketing'!DK28+'Sales'!DK24+'Customer Success'!DK33+'Engineering'!DK27-'Engineering'!DK11+'Finance'!DK38 | DL10: =IF(COUNT('Marketing'!DL28,'Sales'!DL24,'Customer Success'!DL33,'Engineering'!DL27,'Finance'!DL38,'Engineering'!DL11)=6,'Marketing'!DL28+'Sales'!DL24+'Customer Success'!DL33+'Engineering'!DL27-'Engineering'!DL11+'Finance'!DL38,"") | DM10: ='Marketing'!DM28+'Sales'!DM24+'Customer Success'!DM33+'Engineering'!DM27-'Engineering'!DM11+'Finance'!DM38 | DN10: ='Marketing'!DN28+'Sales'!DN24+'Customer Success'!DN33+'Engineering'!DN27-'Engineering'!DN11+'Finance'!DN38
